Workbook

Sheet Kapacity fondu v síti - vzor
A1: Pobočka č. | B1: Pobočka | C1: Oblast | D1: Lokace - systémové označení (Koniáš) | E1: Typ | F1: Označení | G1: Kapacita svazky | H1: Kapacita - počet polic | I1: Kapacita - současný stav | J1: Kapacita - rozměr polic | K1: Poznámka | L1: Jakou byste doporučili ideální naplněnost?
A2: =IFERROR(VLOOKUP(B2,Pobočky!$A$1:$C$45,3,FALSE)," ") -> 29 | B2: Smíchov | C2: =IFERROR(VLOOKUP(B2,Pobočky!$A$1:$C$45,2,FALSE)," ") -> Jihozápad | D2: SMI-BELDE (beletrie pro děti) | E2: Beletrie - děti | F2: DÍVKA (piktogram) | G2: 20 | H2: 5 | J2: 81 | K2: A1 + A4 | L2: 0.7
A3: 29 | B3: Smíchov | C3: =IFERROR(VLOOKUP(B3,Pobočky!$A$1:$C$45,2,FALSE)," ") -> Jihozápad | D3: SMI-CHRVOL (Příruční sklad - výdej u info bodu 1) | G3: 505 | H3: 10 | J3: 81 | K3: místo využívané na SAMOPRA (čeká na ochy, kompletaci atd.) | L3: 1
A4: 29 | B4: Smíchov | C4: =IFERROR(VLOOKUP(B4,Pobočky!$A$1:$C$45,2,FALSE)," ") -> Jihozápad | D4: SMI-DOPOR (Doporučujeme) | E4: Beletrie - dospělí | F4: A1 | G4: 1170 | H4: 5 | J4: 81 | L4: 0.5
A5: =IFERROR(VLOOKUP(B5,Pobočky!$A$1:$C$45,3,FALSE)," ") -> 29 | B5: Smíchov | C5: =IFERROR(VLOOKUP(B5,Pobočky!$A$1:$C$45,2,FALSE)," ") -> Jihozápad | D5: SMI-DOPOR (Doporučujeme) | E5: Naučná - dospělí | G5: 5 | H5: 5 | J5: 81 | K5: všechny ochy - tématické výstavky | L5: 0.5
A6: =IFERROR(VLOOKUP(B6,Pobočky!$A$1:$C$45,3,FALSE)," ") -> 29 | B6: Smíchov | C6: =IFERROR(VLOOKUP(B6,Pobočky!$A$1:$C$45,2,FALSE)," ") -> Jihozápad | D6: SMI-DOPOR (Doporučujeme) | E6: Beletrie - dospělí | F6: PISTOLE (piktogram) | G6: 450 | H6: 4 | J6: 40 | K6: prezentační stojan | L6: 0.3
A7: =IFERROR(VLOOKUP(B7,Pobočky!$A$1:$C$45,3,FALSE)," ") | C7: =IFERROR(VLOOKUP(B7,Pobočky!$A$1:$C$45,2,FALSE)," ") | G7: 280
A8: =IFERROR(VLOOKUP(B8,Pobočky!$A$1:$C$45,3,FALSE)," ") | C8: =IFERROR(VLOOKUP(B8,Pobočky!$A$1:$C$45,2,FALSE)," ") | G8: 30
A9: 48 | B9: Ostrovského | C9: =IFERROR(VLOOKUP(B9,Pobočky!$A$1:$C$45,2,FALSE)," ") -> Jihozápad | D9: OSV-NAUDO (XYZ) | E9: Naučná - děti | F9: X | G9: 100 | H9: 0.25 | J9: 80 | L9: 0.7
A10: 48 | B10: Ostrovského | C10: =IFERROR(VLOOKUP(B10,Pobočky!$A$1:$C$45,2,FALSE)," ") -> Jihozápad | D10: OSV-NAUDO (XYZ) | E10: Naučná - dospělí | F10: X | G10: 5 | H10: 1.75 | J10: 80 | L10: 0.7
A11: =IFERROR(VLOOKUP(B11,Pobočky!$A$1:$C$45,3,FALSE)," ") | C11: =IFERROR(VLOOKUP(B11,Pobočky!$A$1:$C$45,2,FALSE)," ") | G11: 185
A12: =IFERROR(VLOOKUP(B12,Pobočky!$A$1:$C$45,3,FALSE)," ") | C12: =IFERROR(VLOOKUP(B12,Pobočky!$A$1:$C$45,2,FALSE)," ") | G12: 5
A13: =IFERROR(VLOOKUP(B13,Pobočky!$A$1:$C$45,3,FALSE)," ") -> 81 | B13: Lužiny | C13: =IFERROR(VLOOKUP(B13,Pobočky!$A$1:$C$45,2,FALSE)," ") -> Jihozápad | D13: LUZ-CIZJAZ (Cizojazyčná + sci-fi a fantasy) | E13: Beletrie - dospělí | F13: MÁG (piktogram) | G13: 5 | H13: 22 | J13: 81 | K13: A1 | L13: 0.7
A14: =IFERROR(VLOOKUP(B14,Pobočky!$A$1:$C$45,3,FALSE)," ") -> 81 | B14: Lužiny | C14: =IFERROR(VLOOKUP(B14,Pobočky!$A$1:$C$45,2,FALSE)," ") -> Jihozápad | D14: LUZ-CIZJAZ (Cizojazyčná + sci-fi a fantasy) | E14: Beletrie - děti | F14: MÁG (piktogram) | G14: 5 | H14: 7 | J14: 81 | K14: A4 | L14: 0.7
A15: =IFERROR(VLOOKUP(B15,Pobočky!$A$1:$C$45,3,FALSE)," ") -> 81 | B15: Lužiny | C15: =IFERROR(VLOOKUP(B15,Pobočky!$A$1:$C$45,2,FALSE)," ") -> Jihozápad | D15: LUZ-CIZJAZ (Cizojazyčná + sci-fi a fantasy) | E15: Beletrie - dospělí | F15: E.T. (piktogram) | G15: 35 | H15: 15 | J15: 81 | K15: A1 | L15: 0.7
A16: =IFERROR(VLOOKUP(B16,Pobočky!$A$1:$C$45,3,FALSE)," ") -> 81 | B16: Lužiny | C16: =IFERROR(VLOOKUP(B16,Pobočky!$A$1:$C$45,2,FALSE)," ") -> Jihozápad | D16: LUZ-CIZJAZ (Cizojazyčná + sci-fi a fantasy) | E16: Beletrie - děti | F16: E.T. (piktogram) | G16: 110 | H16: 1.5 | J16: 81 | K16: A4 | L16: 0.7
A17: =IFERROR(VLOOKUP(B17,Pobočky!$A$1:$C$45,3,FALSE)," ") -> 81 | B17: Lužiny | C17: =IFERROR(VLOOKUP(B17,Pobočky!$A$1:$C$45,2,FALSE)," ") -> Jihozápad | D17: LUZ-CIZJAZ (Cizojazyčná + sci-fi a fantasy) | E17: Beletrie - dospělí | F17: komiksy | G17: 20 | H17: 10 | J17: 81 | K17: včetně naučných komiksů | L17: 0.5
A18: =IFERROR(VLOOKUP(B18,Pobočky!$A$1:$C$45,3,FALSE)," ") | C18: =IFERROR(VLOOKUP(B18,Pobočky!$A$1:$C$45,2,FALSE)," ") | G18: 1
A19: =IFERROR(VLOOKUP(B19,Pobočky!$A$1:$C$45,3,FALSE)," ") | C19: =IFERROR(VLOOKUP(B19,Pobočky!$A$1:$C$45,2,FALSE)," ") | G19: 1
A20: =IFERROR(VLOOKUP(B20,Pobočky!$A$1:$C$45,3,FALSE)," ") -> 56 | B20: Dům čtení | C20: =IFERROR(VLOOKUP(B20,Pobočky!$A$1:$C$45,2,FALSE)," ") -> Jihovýchod | D20: RUS-BELDO | E20: Beletrie - dospělí | F20: A1 | G20: 1 | K20: Piktogram KMET (různé OCHy, beletrie i naučná)
A21: =IFERROR(VLOOKUP(B21,Pobočky!$A$1:$C$45,3,FALSE)," ") -> 56 | B21: Dům čtení | C21: =IFERROR(VLOOKUP(B21,Pobočky!$A$1:$C$45,2,FALSE)," ") -> Jihovýchod | D21: RUS-BELDO | E21: Beletrie - dospělí | F21: A1 | G21: 1 | K21: Piktogram KOVBOJ
A22: =IFERROR(VLOOKUP(B22,Pobočky!$A$1:$C$45,3,FALSE)," ") -> 56 | B22: Dům čtení | C22: =IFERROR(VLOOKUP(B22,Pobočky!$A$1:$C$45,2,FALSE)," ") -> Jihovýchod | D22: RUS-BELDO | E22: Beletrie - dospělí | F22: A1 | G22: 1 | K22: Piktogram LEBKA
A24: =IFERROR(VLOOKUP(B24,Pobočky!$A$1:$C$45,3,FALSE)," ") | C24: =IFERROR(VLOOKUP(B24,Pobočky!$A$1:$C$45,2,FALSE)," ") | G24: 370
A25: =IFERROR(VLOOKUP(B25,Pobočky!$A$1:$C$45,3,FALSE)," ") | C25: =IFERROR(VLOOKUP(B25,Pobočky!$A$1:$C$45,2,FALSE)," ") | G25: 7600
A26: =IFERROR(VLOOKUP(B26,Pobočky!$A$1:$C$45,3,FALSE)," ") | C26: =IFERROR(VLOOKUP(B26,Pobočky!$A$1:$C$45,2,FALSE)," ") | G26: 660
A27: =IFERROR(VLOOKUP(B27,Pobočky!$A$1:$C$45,3,FALSE)," ") | C27: =IFERROR(VLOOKUP(B27,Pobočky!$A$1:$C$45,2,FALSE)," ") | G27: 150
A28: =IFERROR(VLOOKUP(B28,Pobočky!$A$1:$C$45,3,FALSE)," ") | C28: =IFERROR(VLOOKUP(B28,Pobočky!$A$1:$C$45,2,FALSE)," ") | G28: 1040
A29: =IFERROR(VLOOKUP(B29,Pobočky!$A$1:$C$45,3,FALSE)," ") | C29: =IFERROR(VLOOKUP(B29,Pobočky!$A$1:$C$45,2,FALSE)," ") | G29: 20
A30: =IFERROR(VLOOKUP(B30,Pobočky!$A$1:$C$45,3,FALSE)," ") | C30: =IFERROR(VLOOKUP(B30,Pobočky!$A$1:$C$45,2,FALSE)," ") | G30: 40
A31: =IFERROR(VLOOKUP(B31,Pobočky!$A$1:$C$45,3,FALSE)," ") | C31: =IFERROR(VLOOKUP(B31,Pobočky!$A$1:$C$45,2,FALSE)," ") | G31: 70
A32: =IFERROR(VLOOKUP(B32,Pobočky!$A$1:$C$45,3,FALSE)," ") | C32: =IFERROR(VLOOKUP(B32,Pobočky!$A$1:$C$45,2,FALSE)," ") | G32: 330
A33: =IFERROR(VLOOKUP(B33,Pobočky!$A$1:$C$45,3,FALSE)," ") | C33: =IFERROR(VLOOKUP(B33,Pobočky!$A$1:$C$45,2,FALSE)," ") | G33: 40
A34: =IFERROR(VLOOKUP(B34,Pobočky!$A$1:$C$45,3,FALSE)," ") | C34: =IFERROR(VLOOKUP(B34,Pobočky!$A$1:$C$45,2,FALSE)," ") | G34: 20
A35: =IFERROR(VLOOKUP(B35,Pobočky!$A$1:$C$45,3,FALSE)," ") | C35: =IFERROR(VLOOKUP(B35,Pobočky!$A$1:$C$45,2,FALSE)," ") | G35: 40
... A97: =IFERROR(VLOOKUP(B97,Pobočky!$A$1:$C$45,3,FALSE)," ") | C97: =IFERROR(VLOOKUP(B97,Pobočky!$A$1:$C$45,2,FALSE)," ") | G97: 490

Sheet Kapacity fondu v síti - vzor2
A1: Pobočka č. | B1: Pobočka | C1: Oblast | D1: Lokace - systémové označení (Koniáš) | E1: Typ | F1: Označení | G1: Kapacita svazky | H1: Kapacita - počet polic | I1: Kapacita - současný stav | J1: Kapacita - rozměr polic | K1: Poznámka | L1: Jakou byste doporučili ideální naplněnost?
A2: =IFERROR(VLOOKUP(B2,Pobočky!$A$1:$C$45,3,FALSE)," ") | C2: =IFERROR(VLOOKUP(B2,Pobočky!$A$1:$C$45,2,FALSE)," ")
A3: =IFERROR(VLOOKUP(B3,Pobočky!$A$1:$C$45,3,FALSE)," ") | C3: =IFERROR(VLOOKUP(B3,Pobočky!$A$1:$C$45,2,FALSE)," ")
A4: =IFERROR(VLOOKUP(B4,Pobočky!$A$1:$C$45,3,FALSE)," ") | C4: =IFERROR(VLOOKUP(B4,Pobočky!$A$1:$C$45,2,FALSE)," ")
A5: =IFERROR(VLOOKUP(B5,Pobočky!$A$1:$C$45,3,FALSE)," ") | C5: =IFERROR(VLOOKUP(B5,Pobočky!$A$1:$C$45,2,FALSE)," ")
A6: =IFERROR(VLOOKUP(B6,Pobočky!$A$1:$C$45,3,FALSE)," ") | C6: =IFERROR(VLOOKUP(B6,Pobočky!$A$1:$C$45,2,FALSE)," ")
A7: =IFERROR(VLOOKUP(B7,Pobočky!$A$1:$C$45,3,FALSE)," ") | C7: =IFERROR(VLOOKUP(B7,Pobočky!$A$1:$C$45,2,FALSE)," ")
A8: =IFERROR(VLOOKUP(B8,Pobočky!$A$1:$C$45,3,FALSE)," ") | C8: =IFERROR(VLOOKUP(B8,Pobočky!$A$1:$C$45,2,FALSE)," ")
A9: =IFERROR(VLOOKUP(B9,Pobočky!$A$1:$C$45,3,FALSE)," ") | C9: =IFERROR(VLOOKUP(B9,Pobočky!$A$1:$C$45,2,FALSE)," ")
A10: =IFERROR(VLOOKUP(B10,Pobočky!$A$1:$C$45,3,FALSE)," ") | C10: =IFERROR(VLOOKUP(B10,Pobočky!$A$1:$C$45,2,FALSE)," ")
A11: =IFERROR(VLOOKUP(B11,Pobočky!$A$1:$C$45,3,FALSE)," ") | C11: =IFERROR(VLOOKUP(B11,Pobočky!$A$1:$C$45,2,FALSE)," ")
A12: =IFERROR(VLOOKUP(B12,Pobočky!$A$1:$C$45,3,FALSE)," ") | C12: =IFERROR(VLOOKUP(B12,Pobočky!$A$1:$C$45,2,FALSE)," ")
A13: =IFERROR(VLOOKUP(B13,Pobočky!$A$1:$C$45,3,FALSE)," ") | C13: =IFERROR(VLOOKUP(B13,Pobočky!$A$1:$C$45,2,FALSE)," ")
... A417: =IFERROR(VLOOKUP(B417,Pobočky!$A$1:$C$45,3,FALSE)," ") | C417: =IFERROR(VLOOKUP(B417,Pobočky!$A$1:$C$45,2,FALSE)," ")

Sheet Pobočky
A1: Název | B1: Oblast | C1: Číslo
A2: Ústřední knihovna
A3: Hradčany | B3: Středozápad | C3: 3
A4: Ostrčilovo náměstí | B4: Středozápad | C4: 4
A5: Školská | B5: Středozápad | C5: 8
A6: Žižkov | B6: Středozápad | C6: 15
A7: Břevnov | B7: Středozápad | C7: 35
A8: Dědina | B8: Středozápad | C8: 37
A9: Dejvice | B9: Středozápad | C9: 38
A10: Petřiny | B10: Středozápad | C10: 42
A11: Dittrichova | B11: Středozápad | C11: 51
A12: Záhřebská | B12: Středozápad | C12: 65
A13: Vozovna | B13: Středozápad | C13: 66
A14: Sedmička | B14: Severovýchod | C14: 5
... A45: Stodůlky | B45: Jihozápad | C45: 84

Sheet Označení
A1: Označení | D1: och | E1: popis | F1: OCHy a piktogramy | G1: Koeficient
A2: PRINCEZNA (piktogram) | D2: J | E2: CIZOJAZYČNÁ BELETRIE. | F2: J - CIZOJAZYČNÁ BELETRIE. | G2: 0.36 | J2: DOSPĚLÍ 100%
A3: DÍVKA (piktogram) | D3: A | E3: BELETRIE VŠEOBECNĚ. | F3: J1-J5 | G3: 0.36 | J3: OCH | K3: počet sv. na 1 cm reg.
A4: PEGAS (piktogram) | D4: B | E4: POEZIE. | F4: J6-J14 | G4: 0.36 | J4: A1 | K4: 0.33
A5: ÚSMĚV (piktogram) | D5: C | E5: DOMÁCNOST. | F5: A1 - beletrie pro dospělé čtenáře a mládež v češtině | G5: 0.33 | J5: J1-J5 | K5: 0.36
A6: poezie děti | D6: D | E6: DĚJINY. DĚJEPIS. | F6: A2 - knížky pro předškolní děti v češtině | G6: 0.83 | J6: J6-J14 | K6: 0.36
A7: PISTOLE (piktogram) | D7: E | E7: ZEMĚPIS. VLASTIVĚDA. ETNOGRAFIE. | F7: A3 – knížky pro děti do deseti let v češtině | G7: 0.64 | J7: B2 | K7: 0.57
A8: ost. cizojazyčná | D8: G | E8: SPOLEČENSKÉ VĚDY. | F8: A4 – próza pro starší děti v češtině | G8: 0.43 | J8: B1 | K8: 0.42
A9: MÁG (piktogram) | D9: K | E9: PŘÍRODNÍ VĚDY. | F9: B1 – dramatická literatura, divadelní hry, rozhlasové hry, filmové a televizní scénáře | G9: 0.42
A10: E.T. (piktogram) | D10: L | E10: FILOZOFIE. PSYCHOLOGIE. ESTETIKA. ETIKA. LOGIKA. NÁBOŽENSTVÍ. | F10: A - BELETRIE VŠEOBECNĚ. | G10: 0.56 | J10: C | K10: 0.62
A11: komiksy | D11: N | E11: PEDAGOGIKA. ŠKOLSTVÍ. VÝCHOVA. VZDĚLÁVÁNÍ. | F11: B1 – dramatická literatura, divadelní hry, rozhlasové hry, filmové a televizní scénáře | G11: 0.42 | J11: D | K11: 0.38
A12: leporela | D12: O | E12: PRÁVO. PRÁVNÍ VĚDA. | F12: B2 – poezie v češtině pro dospělé, mládež a starší děti | G12: 0.57 | J12: E | K12: 0.55
A13: ost. naučná | D13: P | E13: LÉKAŘSTVÍ A ZDRAVOTNICTVÍ. | F13: C - DOMÁCNOST. | G13: 0.62 | J13: G | K13: 0.42
A14: A1 | D14: R | E14: JAZYKOVĚDA. | F14: D - DĚJINY. DĚJEPIS. | G14: 0.38 | J14: K | K14: 0.51
A15: J1-J5 | D15: S | E15: UMĚNÍ. | F15: E - ZEMĚPIS. VLASTIVĚDA. ETNOGRAFIE. | G15: 0.55 | J15: L | K15: 0.47
A16: J6-J14 | D16: T | E16: TECHNIKA. | F16: G - SPOLEČENSKÉ VĚDY. | G16: 0.42 | J16: N | K16: 0.59
A17: B2 | D17: U | E17: VŠEOBECNÉ ENCYKLOPEDIE. | F17: GOW - společný OCH | G17: 0.7 | J17: O | K17: 0.53
A18: B1 | D18: V | E18: HUDBA. | F18: K - PŘÍRODNÍ VĚDY. | G18: 0.51 | J18: P | K18: 0.55
A19: C | D19: W | E19: VOJENSTVÍ. | F19: L - FILOZOFIE. PSYCHOLOGIE. ESTETIKA. ETIKA. LOGIKA. NÁBOŽENSTVÍ. | G19: 0.47 | J19: R | K19: 0.5
A20: D | D20: X | E20: LITERATURA. | F20: N - PEDAGOGIKA. ŠKOLSTVÍ. VÝCHOVA. VZDĚLÁVÁNÍ. | G20: 0.59 | J20: S | K20: 0.46
A21: E | D21: Y | E21: TĚLESNÁ VÝCHOVA A SPORT | F21: O - PRÁVO. PRÁVNÍ VĚDA. | G21: 0.53 | J21: T | K21: 0.59
A22: G | D22: Z | E22: ZEMĚDĚLSTVÍ. LESNICTVÍ. MYSLIVOST. | F22: P - LÉKAŘSTVÍ A ZDRAVOTNICTVÍ. | G22: 0.55 | J22: U | K22: 0.17
A23: K | F23: R - JAZYKOVĚDA. | G23: 0.5 | J23: VT | K23: 0.46
A24: L | F24: S - UMĚNÍ. | G24: 0.46 | J24: W | K24: 0.42
A25: N | F25: T - TECHNIKA. | G25: 0.59 | J25: X | K25: 0.39
A26: O | F26: U - VŠEOBECNÉ ENCYKLOPEDIE. | G26: 0.17 | J26: Y | K26: 0.56
A27: P | F27: V - HUDBA. | G27: 0.46 | J27: Z | K27: 0.67
A28: R | F28: W - VOJENSTVÍ. | G28: 0.42
A29: S | F29: X - LITERATURA. | G29: 0.39
A30: T | F30: Y - TĚLESNÁ VÝCHOVA A SPORT | G30: 0.56
A31: U | F31: Z - ZEMĚDĚLSTVÍ. LESNICTVÍ. MYSLIVOST. | G31: 0.67
A32: VT | F32: Leporela
A33: W | F33: Komiksy pro děti
A34: X | F34: Komiksy pro dospělé
A35: Y | F35: LEBKA - horory | G35: 0.3
A36: Z | F36: PISTOLE - detektivky | G36: 0.3
A37: A2 | F37: MILENCI - pro ženy | G37: 0.32
A38: A3 | F38: ÚSMĚV - humoristická | G38: 0.39
A39: A4 | F39: ERB - historická
A40: J1 - J14 | F40: DÍVKA - dívčí četba | G40: 0.42
...

Sheet nové koeficienty 100%
A1: Metodika počítání kapacity pobočky - počty svazků 100% naplněnost
A3: DOSPĚLÍ 100% | D3: DĚTI 100% | G3: PIKTOGRAMY 100%
A4: OCH | B4: počet sv. na 1 cm reg. | D4: OCH | E4: počet sv. na 1 cm reg. | G4: PIKTOGRAM | H4: počet sv. na 1 cm reg.
A5: A1 | B5: 0.33 | D5: A2 | E5: 0.83 | G5: pohádky, princezna | H5: 0.62
A6: J1-J5 | B6: 0.36 | D6: A3 | E6: 0.64 | G6: báje, pegas | H6: 0.42
A7: J6-J14 | B7: 0.36 | D7: A4 | E7: 0.43 | G7: humor, úsměv | H7: 0.39
A8: B2 | B8: 0.57 | D8: J1 - J14 | E8: 0.72 | G8: dívčí, dívka | H8: 0.42
A9: B1 | B9: 0.42 | D9: B2 | E9: 0.76 | G9: pistole | H9: 0.3
G10: E.T. | H10: 0.32
A11: C | B11: 0.62 | D11: C | E11: 1 | G11: mág | H11: 0.31
A12: D | B12: 0.38 | D12: D | E12: 0.72 | G12: milenci | H12: 0.32
A13: E | B13: 0.55 | D13: E | E13: 0.78 | G13: lebka | H13: 0.3
A14: G | B14: 0.42 | D14: G | E14: 0.88 | G14: Tam, kde jsou samostatné piktogr. regály
A15: K | B15: 0.51 | D15: K | E15: 0.77 | G15: Kde nejsou, počítáme koef. pro OCH
A16: L | B16: 0.47 | D16: L | E16: 0.73
A17: N | B17: 0.59 | D17: N | E17: 0.82
A18: O | B18: 0.53 | D18: O | E18: 0.7
A19: P | B19: 0.55 | D19: P | E19: 0.73 | G19: sig. G,O,W většinou dohromady s koef. 0,7
A20: R | B20: 0.5 | D20: R | E20: 0.78
A21: S | B21: 0.46 | D21: S | E21: 0.75
A22: T | B22: 0.59 | D22: T | E22: 0.75
A23: U | B23: 0.17 | D23: U | E23: 0.48
A24: VT | B24: 0.46 | D24: VT | E24: 0.76
A25: W | B25: 0.42 | D25: W | E25: 0.7
A26: X | B26: 0.39 | D26: X | E26: 0.9
A27: Y | B27: 0.56 | D27: Y | E27: 0.72
A28: Z | B28: 0.67 | D28: Z | E28: 0.75

Sheet původní kapacitní plán pro OIT
A1: POBOČKA Č. | B1: LOKACE | C1: OCH | D1: VĚK | E1: DESKRIPTOR … | F1: KAPACITA
A2: 29 | B2: SMI-BELDE | C2: A1 | D2: vše | F2: 20
A3: 29 | B3: SMI-BELDE | C3: A2 | D3: vše | F3: 505
A4: 29 | B4: SMI-BELDE | C4: A3 | D4: vše | F4: 1170
A5: 29 | B5: SMI-BELDE | C5: A4 | D5: vše | F5: 5
A6: 29 | B6: SMI-BELDE | D6: vše | E6: PRINCEZNA (piktogram) | F6: 450
A7: 29 | B7: SMI-BELDE | D7: děti | E7: DÍVKA (piktogram) | F7: 280
A8: 29 | B8: SMI-BELDE | D8: dospělí | E8: DÍVKA (piktogram) | F8: 30
A9: 29 | B9: SMI-BELDE | D9: děti | E9: PEGAS (piktogram) | F9: 100
A10: 29 | B10: SMI-BELDE | D10: dospělí | E10: PEGAS (piktogram) | F10: 5
A11: 29 | B11: SMI-BELDE | D11: děti | E11: ÚSMĚV (piktogram) | F11: 185
A12: 29 | B12: SMI-BELDE | D12: dospělí | E12: ÚSMĚV (piktogram) | F12: 5
A13: 29 | B13: SMI-BELDE | C13: J1 | D13: děti | F13: 5
A14: 29 | B14: SMI-BELDE | C14: J2 | D14: děti | F14: 5
A15: 29 | B15: SMI-BELDE | C15: J3 | D15: děti | F15: 35
A16: 29 | B16: SMI-BELDE | C16: J4 | D16: děti | F16: 110
A17: 29 | B17: SMI-BELDE | C17: J5 | D17: děti | F17: 20
A18: 29 | B18: SMI-BELDE | C18: J1 | D18: dospělí | F18: 1
A19: 29 | B19: SMI-BELDE | C19: J2 | D19: dospělí | F19: 1
A20: 29 | B20: SMI-BELDE | C20: J3 | D20: dospělí | F20: 1
A21: 29 | B21: SMI-BELDE | C21: J4 | D21: dospělí | F21: 1
A22: 29 | B22: SMI-BELDE | C22: J5 | D22: dospělí | F22: 1
A23: 29 | B23: SMI-BELDE | C23: B2 | D23: dospělí | F23: 5
A24: 29 | B24: SMI-BELDE | D24: děti | E24: poezie děti | F24: 370
A25: 29 | B25: SMI-BELDO | C25: A1 | D25: vše | F25: 7600
A26: 29 | B26: SMI-BELDO | C26: A1 | D26: vše | E26: PISTOLE (piktogram) | F26: 660
A27: 29 | B27: SMI-BELDO | C27: B1 | D27: vše | F27: 150
A28: 29 | B28: SMI-BELDO | C28: B2 | D28: vše | F28: 1040
A29: 29 | B29: SMI-BELDO | C29: J1 | D29: vše | F29: 20
A30: 29 | B30: SMI-BELDO | C30: J2 | D30: vše | F30: 40
A31: 29 | B31: SMI-BELDO | C31: J3 | D31: vše | F31: 70
A32: 29 | B32: SMI-BELDO | C32: J4 | D32: vše | F32: 330
A33: 29 | B33: SMI-BELDO | C33: J5 | D33: vše | F33: 40
A34: 29 | B34: SMI-BELDO | D34: vše | E34: ost. cizojazyčná | F34: 20
A35: 29 | B35: SMI-GALDE | C35: A1 | D35: děti | F35: 40
A36: 29 | B36: SMI-GALDE | C36: A1 | D36: dospělí | F36: 10
A37: 29 | B37: SMI-GALDE | C37: A4 | D37: vše | F37: 1000
A38: 29 | B38: SMI-GALDE | D38: děti | E38: MÁG (piktogram) | F38: 100
A39: 29 | B39: SMI-GALDE | D39: dospělí | E39: MÁG (piktogram) | F39: 10
A40: 29 | B40: SMI-GALDE | D40: děti | E40: E.T. (piktogram) | F40: 35
...

Sheet počítání
E1: skutečný | F1: vnitřní šířka | G1: starý | H1: zde vzorec | I1: současná | J1: nový | K1: zde vzorec pro počet svazků | N1: nová | O1: aktuální
A2: pobočka číslo | B2: lokace | C2: OCH | D2: pikt/deskr. | E2: počet polic | F2: police (cm) | G2: koefic. | H2: počet sv. | I2: kapacita | J2: koefic. | K2: 1 | L2: 0.7 | M2: 0.6 | N2: kapacita | O2: naplněnost
H3: =ROUND(E3*F3*G3,0) -> 0 | K3: =ROUND(E3*F3*J3,0) -> 0 | L3: =ROUND(K3*0.7,0) -> 0 | M3: =ROUND(K3*0.6,0) -> 0
H4: =ROUND(E4*F4*G4,0) -> 0 | K4: =ROUND(E4*F4*J4,0) -> 0 | L4: =ROUND(K4*0.7,0) -> 0 | M4: =ROUND(K4*0.6,0) -> 0
H5: =ROUND(E5*F5*G5,0) -> 0 | K5: =ROUND(E5*F5*J5,0) -> 0 | L5: =ROUND(K5*0.7,0) -> 0 | M5: =ROUND(K5*0.6,0) -> 0
H6: =ROUND(E6*F6*G6,0) -> 0 | K6: =ROUND(E6*F6*J6,0) -> 0 | L6: =ROUND(K6*0.7,0) -> 0 | M6: =ROUND(K6*0.6,0) -> 0
H7: =ROUND(E7*F7*G7,0) -> 0 | K7: =ROUND(E7*F7*J7,0) -> 0 | L7: =ROUND(K7*0.7,0) -> 0 | M7: =ROUND(K7*0.6,0) -> 0
H8: =ROUND(E8*F8*G8,0) -> 0 | K8: =ROUND(E8*F8*J8,0) -> 0 | L8: =ROUND(K8*0.7,0) -> 0 | M8: =ROUND(K8*0.6,0) -> 0
H9: =ROUND(E9*F9*G9,0) -> 0 | K9: =ROUND(E9*F9*J9,0) -> 0 | L9: =ROUND(K9*0.7,0) -> 0 | M9: =ROUND(K9*0.6,0) -> 0
H10: =ROUND(E10*F10*G10,0) -> 0 | K10: =ROUND(E10*F10*J10,0) -> 0 | L10: =ROUND(K10*0.7,0) -> 0 | M10: =ROUND(K10*0.6,0) -> 0
H11: =ROUND(E11*F11*G11,0) -> 0 | K11: =ROUND(E11*F11*J11,0) -> 0 | L11: =ROUND(K11*0.7,0) -> 0 | M11: =ROUND(K11*0.6,0) -> 0
H12: =ROUND(E12*F12*G12,0) -> 0 | K12: =ROUND(E12*F12*J12,0) -> 0 | L12: =ROUND(K12*0.7,0) -> 0 | M12: =ROUND(K12*0.6,0) -> 0
H13: =ROUND(E13*F13*G13,0) -> 0 | K13: =ROUND(E13*F13*J13,0) -> 0 | L13: =ROUND(K13*0.7,0) -> 0 | M13: =ROUND(K13*0.6,0) -> 0
H14: =ROUND(E14*F14*G14,0) -> 0 | K14: =ROUND(E14*F14*J14,0) -> 0 | L14: =ROUND(K14*0.7,0) -> 0 | M14: =ROUND(K14*0.6,0) -> 0
... H75: =ROUND(E75*F75*G75,0) -> 0 | K75: =ROUND(E75*F75*J75,0) -> 0 | L75: =ROUND(K75*0.7,0) -> 0 | M75: =ROUND(K75*0.6,0) -> 0

Sheet Barrandov
A1: Pobočka č. | B1: Pobočka | C1: Oblast | D1: Lokace - systémové označení (Koniáš) | E1: Typ | F1: Označení | G1: Kapacita svazky | H1: Kapacita - počet polic | I1: Kapacita - současný stav | J1: Kapacita - rozměr polic | K1: Poznámka | L1: Jakou byste doporučili ideální naplněnost?
A2: =IFERROR(VLOOKUP(B2,Pobočky!$A$1:$C$45,3,FALSE)," ") -> 62 | B2: Barrandov | C2: =IFERROR(VLOOKUP(B2,Pobočky!$A$1:$C$45,2,FALSE)," ") -> Jihozápad | D2: BAR-BELDE | E2: Beletrie - děti | F2: A - BELETRIE VŠEOBECNĚ. | G2: =ROUND(Tabulka5789101112131415161718192021222324252627282930313233343536373839404142434445464748[[#This Row],[Kapacita - počet polic]]*Tabulka5789101112131415161718192021222324252627282930313233343536373839404142434445464748[[#This Row],[Kapacita - rozměr polic]]*IFERROR(VLOOKUP(Tabulka5789101112131415161718192021222324252627282930313233343536373839404142434445464748[[#This Row],[Označení]],OCHy[#All],2,FALSE),0.6),0) -> 1156 | H2: 24 | J2: 86 | K2: A2 + A3 | L2: 0.7
A3: =IFERROR(VLOOKUP(B3,Pobočky!$A$1:$C$45,3,FALSE)," ") -> 62 | B3: Barrandov | C3: =IFERROR(VLOOKUP(B3,Pobočky!$A$1:$C$45,2,FALSE)," ") -> Jihozápad | D3: BAR-BELDE | E3: Beletrie - děti | F3: A - BELETRIE VŠEOBECNĚ. | G3: =ROUND(Tabulka5789101112131415161718192021222324252627282930313233343536373839404142434445464748[[#This Row],[Kapacita - počet polic]]*Tabulka5789101112131415161718192021222324252627282930313233343536373839404142434445464748[[#This Row],[Kapacita - rozměr polic]]*IFERROR(VLOOKUP(Tabulka5789101112131415161718192021222324252627282930313233343536373839404142434445464748[[#This Row],[Označení]],OCHy[#All],2,FALSE),0.6),0) -> 771 | H3: 16 | J3: 86 | K3: A1 + A4 | L3: 0.7
A4: =IFERROR(VLOOKUP(B4,Pobočky!$A$1:$C$45,3,FALSE)," ") -> 62 | B4: Barrandov | C4: =IFERROR(VLOOKUP(B4,Pobočky!$A$1:$C$45,2,FALSE)," ") -> Jihozápad | D4: BAR-BELDE | E4: Beletrie - děti | F4: E.T. - sci-fi | G4: =ROUND(Tabulka5789101112131415161718192021222324252627282930313233343536373839404142434445464748[[#This Row],[Kapacita - počet polic]]*Tabulka5789101112131415161718192021222324252627282930313233343536373839404142434445464748[[#This Row],[Kapacita - rozměr polic]]*IFERROR(VLOOKUP(Tabulka5789101112131415161718192021222324252627282930313233343536373839404142434445464748[[#This Row],[Označení]],OCHy[#All],2,FALSE),0.6),0) -> 220 | H4: 8 | J4: 86 | K4: s Mágem | L4: 0.7
A5: =IFERROR(VLOOKUP(B5,Pobočky!$A$1:$C$45,3,FALSE)," ") -> 62 | B5: Barrandov | C5: =IFERROR(VLOOKUP(B5,Pobočky!$A$1:$C$45,2,FALSE)," ") -> Jihozápad | D5: BAR-BELDE | E5: Beletrie - děti | F5: J - CIZOJAZYČNÁ BELETRIE. | G5: =ROUND(Tabulka5789101112131415161718192021222324252627282930313233343536373839404142434445464748[[#This Row],[Kapacita - počet polic]]*Tabulka5789101112131415161718192021222324252627282930313233343536373839404142434445464748[[#This Row],[Kapacita - rozměr polic]]*IFERROR(VLOOKUP(Tabulka5789101112131415161718192021222324252627282930313233343536373839404142434445464748[[#This Row],[Označení]],OCHy[#All],2,FALSE),0.6),0) -> 31 | H5: 1 | J5: 86 | K5: J1 - J3 | L5: 0.7
A6: =IFERROR(VLOOKUP(B6,Pobočky!$A$1:$C$45,3,FALSE)," ") -> 62 | B6: Barrandov | C6: =IFERROR(VLOOKUP(B6,Pobočky!$A$1:$C$45,2,FALSE)," ") -> Jihozápad | D6: BAR-BELDE | E6: Beletrie - děti | F6: J - CIZOJAZYČNÁ BELETRIE. | G6: =ROUND(Tabulka5789101112131415161718192021222324252627282930313233343536373839404142434445464748[[#This Row],[Kapacita - počet polic]]*Tabulka5789101112131415161718192021222324252627282930313233343536373839404142434445464748[[#This Row],[Kapacita - rozměr polic]]*IFERROR(VLOOKUP(Tabulka5789101112131415161718192021222324252627282930313233343536373839404142434445464748[[#This Row],[Označení]],OCHy[#All],2,FALSE),0.6),0) -> 62 | H6: 2 | J6: 86 | K6: J4 | L6: 0.7
A7: =IFERROR(VLOOKUP(B7,Pobočky!$A$1:$C$45,3,FALSE)," ") -> 62 | B7: Barrandov | C7: =IFERROR(VLOOKUP(B7,Pobočky!$A$1:$C$45,2,FALSE)," ") -> Jihozápad | D7: BAR-BELDE | E7: Beletrie - děti | F7: B - POEZIE. | G7: =ROUND(Tabulka5789101112131415161718192021222324252627282930313233343536373839404142434445464748[[#This Row],[Kapacita - počet polic]]*Tabulka5789101112131415161718192021222324252627282930313233343536373839404142434445464748[[#This Row],[Kapacita - rozměr polic]]*IFERROR(VLOOKUP(Tabulka5789101112131415161718192021222324252627282930313233343536373839404142434445464748[[#This Row],[Označení]],OCHy[#All],2,FALSE),0.6),0) -> 155 | H7: 3 | J7: 86 | L7: 0.7
A8: =IFERROR(VLOOKUP(B8,Pobočky!$A$1:$C$45,3,FALSE)," ") -> 62 | B8: Barrandov | C8: =IFERROR(VLOOKUP(B8,Pobočky!$A$1:$C$45,2,FALSE)," ") -> Jihozápad | D8: BAR-BELDE | E8: Beletrie - děti | F8: DÍVKA - dívčí četba | G8: =ROUND(Tabulka5789101112131415161718192021222324252627282930313233343536373839404142434445464748[[#This Row],[Kapacita - počet polic]]*Tabulka5789101112131415161718192021222324252627282930313233343536373839404142434445464748[[#This Row],[Kapacita - rozměr polic]]*IFERROR(VLOOKUP(Tabulka5789101112131415161718192021222324252627282930313233343536373839404142434445464748[[#This Row],[Označení]],OCHy[#All],2,FALSE),0.6),0) -> 144 | H8: 4 | J8: 86 | L8: 0.7
A9: =IFERROR(VLOOKUP(B9,Pobočky!$A$1:$C$45,3,FALSE)," ") -> 62 | B9: Barrandov | C9: =IFERROR(VLOOKUP(B9,Pobočky!$A$1:$C$45,2,FALSE)," ") -> Jihozápad | D9: BAR-BELDE | E9: Beletrie - děti | F9: PRINCEZNA - pohádky | G9: =ROUND(Tabulka5789101112131415161718192021222324252627282930313233343536373839404142434445464748[[#This Row],[Kapacita - počet polic]]*Tabulka5789101112131415161718192021222324252627282930313233343536373839404142434445464748[[#This Row],[Kapacita - rozměr polic]]*IFERROR(VLOOKUP(Tabulka5789101112131415161718192021222324252627282930313233343536373839404142434445464748[[#This Row],[Označení]],OCHy[#All],2,FALSE),0.6),0) -> 213 | H9: 4 | J9: 86 | L9: 0.7
A10: =IFERROR(VLOOKUP(B10,Pobočky!$A$1:$C$45,3,FALSE)," ") -> 62 | B10: Barrandov | C10: =IFERROR(VLOOKUP(B10,Pobočky!$A$1:$C$45,2,FALSE)," ") -> Jihozápad | D10: BAR-LEPOR | E10: Beletrie - děti | F10: A - BELETRIE VŠEOBECNĚ. | G10: =ROUND(Tabulka5789101112131415161718192021222324252627282930313233343536373839404142434445464748[[#This Row],[Kapacita - počet polic]]*Tabulka5789101112131415161718192021222324252627282930313233343536373839404142434445464748[[#This Row],[Kapacita - rozměr polic]]*IFERROR(VLOOKUP(Tabulka5789101112131415161718192021222324252627282930313233343536373839404142434445464748[[#This Row],[Označení]],OCHy[#All],2,FALSE),0.6),0) -> 0 | K10: leporela (hrabátka - atyp) | L10: 0.5
A11: =IFERROR(VLOOKUP(B11,Pobočky!$A$1:$C$45,3,FALSE)," ") -> 62 | B11: Barrandov | C11: =IFERROR(VLOOKUP(B11,Pobočky!$A$1:$C$45,2,FALSE)," ") -> Jihozápad | D11: BAR-BELDO | E11: Beletrie - dospělí | F11: A - BELETRIE VŠEOBECNĚ. | G11: =ROUND(Tabulka5789101112131415161718192021222324252627282930313233343536373839404142434445464748[[#This Row],[Kapacita - počet polic]]*Tabulka5789101112131415161718192021222324252627282930313233343536373839404142434445464748[[#This Row],[Kapacita - rozměr polic]]*IFERROR(VLOOKUP(Tabulka5789101112131415161718192021222324252627282930313233343536373839404142434445464748[[#This Row],[Označení]],OCHy[#All],2,FALSE),0.6),0) -> 4623 | H11: 96 | J11: 86 | L11: 0.7
A12: =IFERROR(VLOOKUP(B12,Pobočky!$A$1:$C$45,3,FALSE)," ") -> 62 | B12: Barrandov | C12: =IFERROR(VLOOKUP(B12,Pobočky!$A$1:$C$45,2,FALSE)," ") -> Jihozápad | D12: BAR-BELDO | E12: Beletrie - dospělí | F12: A - BELETRIE VŠEOBECNĚ. | G12: =ROUND(Tabulka5789101112131415161718192021222324252627282930313233343536373839404142434445464748[[#This Row],[Kapacita - počet polic]]*Tabulka5789101112131415161718192021222324252627282930313233343536373839404142434445464748[[#This Row],[Kapacita - rozměr polic]]*IFERROR(VLOOKUP(Tabulka5789101112131415161718192021222324252627282930313233343536373839404142434445464748[[#This Row],[Označení]],OCHy[#All],2,FALSE),0.6),0) -> 363 | H12: 18 | J12: 36 | L12: 0.7
A13: =IFERROR(VLOOKUP(B13,Pobočky!$A$1:$C$45,3,FALSE)," ") -> 62 | B13: Barrandov | C13: =IFERROR(VLOOKUP(B13,Pobočky!$A$1:$C$45,2,FALSE)," ") -> Jihozápad | D13: BAR-BELDO | E13: Beletrie - dospělí | F13: PISTOLE - detektivky | G13: =ROUND(Tabulka5789101112131415161718192021222324252627282930313233343536373839404142434445464748[[#This Row],[Kapacita - počet polic]]*Tabulka5789101112131415161718192021222324252627282930313233343536373839404142434445464748[[#This Row],[Kapacita - rozměr polic]]*IFERROR(VLOOKUP(Tabulka5789101112131415161718192021222324252627282930313233343536373839404142434445464748[[#This Row],[Označení]],OCHy[#All],2,FALSE),0.6),0) -> 929 | H13: 36 | J13: 86 | L13: 0.7
A14: =IFERROR(VLOOKUP(B14,Pobočky!$A$1:$C$45,3,FALSE)," ") -> 62 | B14: Barrandov | C14: =IFERROR(VLOOKUP(B14,Pobočky!$A$1:$C$45,2,FALSE)," ") -> Jihozápad | D14: BAR-BELDO | E14: Beletrie - dospělí | F14: E.T. - sci-fi | G14: =ROUND(Tabulka5789101112131415161718192021222324252627282930313233343536373839404142434445464748[[#This Row],[Kapacita - počet polic]]*Tabulka5789101112131415161718192021222324252627282930313233343536373839404142434445464748[[#This Row],[Kapacita - rozměr polic]]*IFERROR(VLOOKUP(Tabulka5789101112131415161718192021222324252627282930313233343536373839404142434445464748[[#This Row],[Označení]],OCHy[#All],2,FALSE),0.6),0) -> 138 | H14: 12 | J14: 36 | L14: 0.7
A15: =IFERROR(VLOOKUP(B15,Pobočky!$A$1:$C$45,3,FALSE)," ") -> 62 | B15: Barrandov | C15: =IFERROR(VLOOKUP(B15,Pobočky!$A$1:$C$45,2,FALSE)," ") -> Jihozápad | D15: BAR-BELDO | E15: Beletrie - dospělí | F15: MÁG - fantasy | G15: =ROUND(Tabulka5789101112131415161718192021222324252627282930313233343536373839404142434445464748[[#This Row],[Kapacita - počet polic]]*Tabulka5789101112131415161718192021222324252627282930313233343536373839404142434445464748[[#This Row],[Kapacita - rozměr polic]]*IFERROR(VLOOKUP(Tabulka5789101112131415161718192021222324252627282930313233343536373839404142434445464748[[#This Row],[Označení]],OCHy[#All],2,FALSE),0.6),0) -> 160 | H15: 6 | J15: 86 | L15: 0.7
A16: =IFERROR(VLOOKUP(B16,Pobočky!$A$1:$C$45,3,FALSE)," ") -> 62 | B16: Barrandov | C16: =IFERROR(VLOOKUP(B16,Pobočky!$A$1:$C$45,2,FALSE)," ") -> Jihozápad | D16: BAR-BELDO | E16: Beletrie - dospělí | F16: J - CIZOJAZYČNÁ BELETRIE. | G16: =ROUND(Tabulka5789101112131415161718192021222324252627282930313233343536373839404142434445464748[[#This Row],[Kapacita - počet polic]]*Tabulka5789101112131415161718192021222324252627282930313233343536373839404142434445464748[[#This Row],[Kapacita - rozměr polic]]*IFERROR(VLOOKUP(Tabulka5789101112131415161718192021222324252627282930313233343536373839404142434445464748[[#This Row],[Označení]],OCHy[#All],2,FALSE),0.6),0) -> 124 | H16: 4 | J16: 86 | K16: J4 | L16: 0.7
A17: =IFERROR(VLOOKUP(B17,Pobočky!$A$1:$C$45,3,FALSE)," ") -> 62 | B17: Barrandov | C17: =IFERROR(VLOOKUP(B17,Pobočky!$A$1:$C$45,2,FALSE)," ") -> Jihozápad | D17: BAR-BELDO | E17: Beletrie - dospělí | F17: J - CIZOJAZYČNÁ BELETRIE. | G17: =ROUND(Tabulka5789101112131415161718192021222324252627282930313233343536373839404142434445464748[[#This Row],[Kapacita - počet polic]]*Tabulka5789101112131415161718192021222324252627282930313233343536373839404142434445464748[[#This Row],[Kapacita - rozměr polic]]*IFERROR(VLOOKUP(Tabulka5789101112131415161718192021222324252627282930313233343536373839404142434445464748[[#This Row],[Označení]],OCHy[#All],2,FALSE),0.6),0) -> 62 | H17: 2 | J17: 86 | K17: ostatní cizojazyčná | L17: 0.7
A18: =IFERROR(VLOOKUP(B18,Pobočky!$A$1:$C$45,3,FALSE)," ") -> 62 | B18: Barrandov | C18: =IFERROR(VLOOKUP(B18,Pobočky!$A$1:$C$45,2,FALSE)," ") -> Jihozápad | D18: BAR-BELDO | E18: Beletrie - dospělí | F18: B - POEZIE. | G18: =ROUND(Tabulka5789101112131415161718192021222324252627282930313233343536373839404142434445464748[[#This Row],[Kapacita - počet polic]]*Tabulka5789101112131415161718192021222324252627282930313233343536373839404142434445464748[[#This Row],[Kapacita - rozměr polic]]*IFERROR(VLOOKUP(Tabulka5789101112131415161718192021222324252627282930313233343536373839404142434445464748[[#This Row],[Označení]],OCHy[#All],2,FALSE),0.6),0) -> 52 | H18: 1 | J18: 86 | K18: divadelní hry | L18: 0.7
A19: =IFERROR(VLOOKUP(B19,Pobočky!$A$1:$C$45,3,FALSE)," ") -> 62 | B19: Barrandov | C19: =IFERROR(VLOOKUP(B19,Pobočky!$A$1:$C$45,2,FALSE)," ") -> Jihozápad | D19: BAR-BELDO | E19: Beletrie - dospělí | F19: B - POEZIE. | G19: =ROUND(Tabulka5789101112131415161718192021222324252627282930313233343536373839404142434445464748[[#This Row],[Kapacita - počet polic]]*Tabulka5789101112131415161718192021222324252627282930313233343536373839404142434445464748[[#This Row],[Kapacita - rozměr polic]]*IFERROR(VLOOKUP(Tabulka5789101112131415161718192021222324252627282930313233343536373839404142434445464748[[#This Row],[Označení]],OCHy[#All],2,FALSE),0.6),0) -> 361 | H19: 7 | J19: 86 | L19: 0.7
A20: =IFERROR(VLOOKUP(B20,Pobočky!$A$1:$C$45,3,FALSE)," ") -> 62 | B20: Barrandov | C20: =IFERROR(VLOOKUP(B20,Pobočky!$A$1:$C$45,2,FALSE)," ") -> Jihozápad | D20: BAR-KOMDE | E20: Beletrie - děti | F20: A - BELETRIE VŠEOBECNĚ. | G20: =ROUND(Tabulka5789101112131415161718192021222324252627282930313233343536373839404142434445464748[[#This Row],[Kapacita - počet polic]]*Tabulka5789101112131415161718192021222324252627282930313233343536373839404142434445464748[[#This Row],[Kapacita - rozměr polic]]*IFERROR(VLOOKUP(Tabulka5789101112131415161718192021222324252627282930313233343536373839404142434445464748[[#This Row],[Označení]],OCHy[#All],2,FALSE),0.6),0) -> 144 | H20: 3 | J20: 86 | K20: komiksy pro děti | L20: 0.4
A21: =IFERROR(VLOOKUP(B21,Pobočky!$A$1:$C$45,3,FALSE)," ") -> 62 | B21: Barrandov | C21: =IFERROR(VLOOKUP(B21,Pobočky!$A$1:$C$45,2,FALSE)," ") -> Jihozápad | D21: BAR-KOMDO | E21: Beletrie - dospělí | F21: A - BELETRIE VŠEOBECNĚ. | G21: =ROUND(Tabulka5789101112131415161718192021222324252627282930313233343536373839404142434445464748[[#This Row],[Kapacita - počet polic]]*Tabulka5789101112131415161718192021222324252627282930313233343536373839404142434445464748[[#This Row],[Kapacita - rozměr polic]]*IFERROR(VLOOKUP(Tabulka5789101112131415161718192021222324252627282930313233343536373839404142434445464748[[#This Row],[Označení]],OCHy[#All],2,FALSE),0.6),0) -> 144 | H21: 3 | J21: 86 | K21: komiksy pro dospělé | L21: 0.4
A22: =IFERROR(VLOOKUP(B22,Pobočky!$A$1:$C$45,3,FALSE)," ") -> 62 | B22: Barrandov | C22: =IFERROR(VLOOKUP(B22,Pobočky!$A$1:$C$45,2,FALSE)," ") -> Jihozápad | D22: BAR-NAUDE | E22: Naučná - děti | F22: C - DOMÁCNOST. | G22: =ROUND(Tabulka5789101112131415161718192021222324252627282930313233343536373839404142434445464748[[#This Row],[Kapacita - počet polic]]*Tabulka5789101112131415161718192021222324252627282930313233343536373839404142434445464748[[#This Row],[Kapacita - rozměr polic]]*IFERROR(VLOOKUP(Tabulka5789101112131415161718192021222324252627282930313233343536373839404142434445464748[[#This Row],[Označení]],OCHy[#All],2,FALSE),0.6),0) -> 53 | H22: 1 | J22: 86 | L22: 0.6
A23: =IFERROR(VLOOKUP(B23,Pobočky!$A$1:$C$45,3,FALSE)," ") -> 62 | B23: Barrandov | C23: =IFERROR(VLOOKUP(B23,Pobočky!$A$1:$C$45,2,FALSE)," ") -> Jihozápad | D23: BAR-NAUDE | E23: Naučná - děti | F23: D - DĚJINY. DĚJEPIS. | G23: =ROUND(Tabulka5789101112131415161718192021222324252627282930313233343536373839404142434445464748[[#This Row],[Kapacita - počet polic]]*Tabulka5789101112131415161718192021222324252627282930313233343536373839404142434445464748[[#This Row],[Kapacita - rozměr polic]]*IFERROR(VLOOKUP(Tabulka5789101112131415161718192021222324252627282930313233343536373839404142434445464748[[#This Row],[Označení]],OCHy[#All],2,FALSE),0.6),0) -> 82 | H23: 2.5 | J23: 86 | L23: 0.6
A24: =IFERROR(VLOOKUP(B24,Pobočky!$A$1:$C$45,3,FALSE)," ") -> 62 | B24: Barrandov | C24: =IFERROR(VLOOKUP(B24,Pobočky!$A$1:$C$45,2,FALSE)," ") -> Jihozápad | D24: BAR-NAUDE | E24: Naučná - děti | F24: E - ZEMĚPIS. VLASTIVĚDA. ETNOGRAFIE. | G24: =ROUND(Tabulka5789101112131415161718192021222324252627282930313233343536373839404142434445464748[[#This Row],[Kapacita - počet polic]]*Tabulka5789101112131415161718192021222324252627282930313233343536373839404142434445464748[[#This Row],[Kapacita - rozměr polic]]*IFERROR(VLOOKUP(Tabulka5789101112131415161718192021222324252627282930313233343536373839404142434445464748[[#This Row],[Označení]],OCHy[#All],2,FALSE),0.6),0) -> 47 | H24: 1 | J24: 86 | L24: 0.6
A25: =IFERROR(VLOOKUP(B25,Pobočky!$A$1:$C$45,3,FALSE)," ") -> 62 | B25: Barrandov | C25: =IFERROR(VLOOKUP(B25,Pobočky!$A$1:$C$45,2,FALSE)," ") -> Jihozápad | D25: BAR-NAUDE | E25: Naučná - děti | F25: K - PŘÍRODNÍ VĚDY. | G25: =ROUND(Tabulka5789101112131415161718192021222324252627282930313233343536373839404142434445464748[[#This Row],[Kapacita - počet polic]]*Tabulka5789101112131415161718192021222324252627282930313233343536373839404142434445464748[[#This Row],[Kapacita - rozměr polic]]*IFERROR(VLOOKUP(Tabulka5789101112131415161718192021222324252627282930313233343536373839404142434445464748[[#This Row],[Označení]],OCHy[#All],2,FALSE),0.6),0) -> 263 | H25: 6 | J25: 86 | L25: 0.6
A26: =IFERROR(VLOOKUP(B26,Pobočky!$A$1:$C$45,3,FALSE)," ") -> 62 | B26: Barrandov | C26: =IFERROR(VLOOKUP(B26,Pobočky!$A$1:$C$45,2,FALSE)," ") -> Jihozápad | D26: BAR-NAUDE | E26: Naučná - děti | F26: L - FILOZOFIE. PSYCHOLOGIE. ESTETIKA. ETIKA. LOGIKA. NÁBOŽENSTVÍ. | G26: =ROUND(Tabulka5789101112131415161718192021222324252627282930313233343536373839404142434445464748[[#This Row],[Kapacita - počet polic]]*Tabulka5789101112131415161718192021222324252627282930313233343536373839404142434445464748[[#This Row],[Kapacita - rozměr polic]]*IFERROR(VLOOKUP(Tabulka5789101112131415161718192021222324252627282930313233343536373839404142434445464748[[#This Row],[Označení]],OCHy[#All],2,FALSE),0.6),0) -> 40 | H26: 1 | J26: 86 | L26: 0.6
A27: =IFERROR(VLOOKUP(B27,Pobočky!$A$1:$C$45,3,FALSE)," ") -> 62 | B27: Barrandov | C27: =IFERROR(VLOOKUP(B27,Pobočky!$A$1:$C$45,2,FALSE)," ") -> Jihozápad | D27: BAR-NAUDE | E27: Naučná - děti | F27: N - PEDAGOGIKA. ŠKOLSTVÍ. VÝCHOVA. VZDĚLÁVÁNÍ. | G27: =ROUND(Tabulka5789101112131415161718192021222324252627282930313233343536373839404142434445464748[[#This Row],[Kapacita - počet polic]]*Tabulka5789101112131415161718192021222324252627282930313233343536373839404142434445464748[[#This Row],[Kapacita - rozměr polic]]*IFERROR(VLOOKUP(Tabulka5789101112131415161718192021222324252627282930313233343536373839404142434445464748[[#This Row],[Označení]],OCHy[#All],2,FALSE),0.6),0) -> 51 | H27: 1 | I27: 1.5 | J27: 86 | L27: 0.6
A28: =IFERROR(VLOOKUP(B28,Pobočky!$A$1:$C$45,3,FALSE)," ") -> 62 | B28: Barrandov | C28: =IFERROR(VLOOKUP(B28,Pobočky!$A$1:$C$45,2,FALSE)," ") -> Jihozápad | D28: BAR-NAUDE | E28: Naučná - děti | F28: P - LÉKAŘSTVÍ A ZDRAVOTNICTVÍ. | G28: =ROUND(Tabulka5789101112131415161718192021222324252627282930313233343536373839404142434445464748[[#This Row],[Kapacita - počet polic]]*Tabulka5789101112131415161718192021222324252627282930313233343536373839404142434445464748[[#This Row],[Kapacita - rozměr polic]]*IFERROR(VLOOKUP(Tabulka5789101112131415161718192021222324252627282930313233343536373839404142434445464748[[#This Row],[Označení]],OCHy[#All],2,FALSE),0.6),0) -> 47 | H28: 1 | J28: 86 | L28: 0.6
A29: =IFERROR(VLOOKUP(B29,Pobočky!$A$1:$C$45,3,FALSE)," ") -> 62 | B29: Barrandov | C29: =IFERROR(VLOOKUP(B29,Pobočky!$A$1:$C$45,2,FALSE)," ") -> Jihozápad | D29: BAR-NAUDE | E29: Naučná - děti | F29: R - JAZYKOVĚDA. | G29: =ROUND(Tabulka5789101112131415161718192021222324252627282930313233343536373839404142434445464748[[#This Row],[Kapacita - počet polic]]*Tabulka5789101112131415161718192021222324252627282930313233343536373839404142434445464748[[#This Row],[Kapacita - rozměr polic]]*IFERROR(VLOOKUP(Tabulka5789101112131415161718192021222324252627282930313233343536373839404142434445464748[[#This Row],[Označení]],OCHy[#All],2,FALSE),0.6),0) -> 43 | H29: 1 | I29: 0.5 | J29: 86 | L29: 0.6
A30: =IFERROR(VLOOKUP(B30,Pobočky!$A$1:$C$45,3,FALSE)," ") -> 62 | B30: Barrandov | C30: =IFERROR(VLOOKUP(B30,Pobočky!$A$1:$C$45,2,FALSE)," ") -> Jihozápad | D30: BAR-NAUDE | E30: Naučná - děti | F30: S - UMĚNÍ. | G30: =ROUND(Tabulka5789101112131415161718192021222324252627282930313233343536373839404142434445464748[[#This Row],[Kapacita - počet polic]]*Tabulka5789101112131415161718192021222324252627282930313233343536373839404142434445464748[[#This Row],[Kapacita - rozměr polic]]*IFERROR(VLOOKUP(Tabulka5789101112131415161718192021222324252627282930313233343536373839404142434445464748[[#This Row],[Označení]],OCHy[#All],2,FALSE),0.6),0) -> 20 | H30: 0.5 | J30: 86 | L30: 0.6
A31: =IFERROR(VLOOKUP(B31,Pobočky!$A$1:$C$45,3,FALSE)," ") -> 62 | B31: Barrandov | C31: =IFERROR(VLOOKUP(B31,Pobočky!$A$1:$C$45,2,FALSE)," ") -> Jihozápad | D31: BAR-NAUDE | E31: Naučná - děti | F31: T - TECHNIKA. | G31: =ROUND(Tabulka5789101112131415161718192021222324252627282930313233343536373839404142434445464748[[#This Row],[Kapacita - počet polic]]*Tabulka5789101112131415161718192021222324252627282930313233343536373839404142434445464748[[#This Row],[Kapacita - rozměr polic]]*IFERROR(VLOOKUP(Tabulka5789101112131415161718192021222324252627282930313233343536373839404142434445464748[[#This Row],[Označení]],OCHy[#All],2,FALSE),0.6),0) -> 51 | H31: 1 | J31: 86 | L31: 0.6
A32: =IFERROR(VLOOKUP(B32,Pobočky!$A$1:$C$45,3,FALSE)," ") -> 62 | B32: Barrandov | C32: =IFERROR(VLOOKUP(B32,Pobočky!$A$1:$C$45,2,FALSE)," ") -> Jihozápad | D32: BAR-NAUDE | E32: Naučná - děti | F32: U - VŠEOBECNÉ ENCYKLOPEDIE. | G32: =ROUND(Tabulka5789101112131415161718192021222324252627282930313233343536373839404142434445464748[[#This Row],[Kapacita - počet polic]]*Tabulka5789101112131415161718192021222324252627282930313233343536373839404142434445464748[[#This Row],[Kapacita - rozměr polic]]*IFERROR(VLOOKUP(Tabulka5789101112131415161718192021222324252627282930313233343536373839404142434445464748[[#This Row],[Označení]],OCHy[#All],2,FALSE),0.6),0) -> 15 | H32: 1 | J32: 86 | L32: 0.6
A33: =IFERROR(VLOOKUP(B33,Pobočky!$A$1:$C$45,3,FALSE)," ") -> 62 | B33: Barrandov | C33: =IFERROR(VLOOKUP(B33,Pobočky!$A$1:$C$45,2,FALSE)," ") -> Jihozápad | D33: BAR-NAUDE | E33: Naučná - děti | F33: V - HUDBA. | G33: =ROUND(Tabulka5789101112131415161718192021222324252627282930313233343536373839404142434445464748[[#This Row],[Kapacita - počet polic]]*Tabulka5789101112131415161718192021222324252627282930313233343536373839404142434445464748[[#This Row],[Kapacita - rozměr polic]]*IFERROR(VLOOKUP(Tabulka5789101112131415161718192021222324252627282930313233343536373839404142434445464748[[#This Row],[Označení]],OCHy[#All],2,FALSE),0.6),0) -> 40 | H33: 1 | J33: 86 | L33: 0.6
A34: =IFERROR(VLOOKUP(B34,Pobočky!$A$1:$C$45,3,FALSE)," ") -> 62 | B34: Barrandov | C34: =IFERROR(VLOOKUP(B34,Pobočky!$A$1:$C$45,2,FALSE)," ") -> Jihozápad | D34: BAR-NAUDE | E34: Naučná - děti | F34: X - LITERATURA. | G34: =ROUND(Tabulka5789101112131415161718192021222324252627282930313233343536373839404142434445464748[[#This Row],[Kapacita - počet polic]]*Tabulka5789101112131415161718192021222324252627282930313233343536373839404142434445464748[[#This Row],[Kapacita - rozměr polic]]*IFERROR(VLOOKUP(Tabulka5789101112131415161718192021222324252627282930313233343536373839404142434445464748[[#This Row],[Označení]],OCHy[#All],2,FALSE),0.6),0) -> 17 | H34: 0.5 | J34: 86 | L34: 0.6
A35: =IFERROR(VLOOKUP(B35,Pobočky!$A$1:$C$45,3,FALSE)," ") -> 62 | B35: Barrandov | C35: =IFERROR(VLOOKUP(B35,Pobočky!$A$1:$C$45,2,FALSE)," ") -> Jihozápad | D35: BAR-NAUDE | E35: Naučná - děti | F35: Y - TĚLESNÁ VÝCHOVA A SPORT | G35: =ROUND(Tabulka5789101112131415161718192021222324252627282930313233343536373839404142434445464748[[#This Row],[Kapacita - počet polic]]*Tabulka5789101112131415161718192021222324252627282930313233343536373839404142434445464748[[#This Row],[Kapacita - rozměr polic]]*IFERROR(VLOOKUP(Tabulka5789101112131415161718192021222324252627282930313233343536373839404142434445464748[[#This Row],[Označení]],OCHy[#All],2,FALSE),0.6),0) -> 48 | H35: 1 | J35: 86 | L35: 0.6
A36: =IFERROR(VLOOKUP(B36,Pobočky!$A$1:$C$45,3,FALSE)," ") -> 62 | B36: Barrandov | C36: =IFERROR(VLOOKUP(B36,Pobočky!$A$1:$C$45,2,FALSE)," ") -> Jihozápad | D36: BAR-NAUDE | E36: Naučná - děti | F36: Z - ZEMĚDĚLSTVÍ. LESNICTVÍ. MYSLIVOST. | G36: =ROUND(Tabulka5789101112131415161718192021222324252627282930313233343536373839404142434445464748[[#This Row],[Kapacita - počet polic]]*Tabulka5789101112131415161718192021222324252627282930313233343536373839404142434445464748[[#This Row],[Kapacita - rozměr polic]]*IFERROR(VLOOKUP(Tabulka5789101112131415161718192021222324252627282930313233343536373839404142434445464748[[#This Row],[Označení]],OCHy[#All],2,FALSE),0.6),0) -> 58 | H36: 1 | J36: 86 | L36: 0.6
A37: =IFERROR(VLOOKUP(B37,Pobočky!$A$1:$C$45,3,FALSE)," ") -> 62 | B37: Barrandov | C37: =IFERROR(VLOOKUP(B37,Pobočky!$A$1:$C$45,2,FALSE)," ") -> Jihozápad | D37: BAR-NAUDE | E37: Naučná - děti | F37: G - SPOLEČENSKÉ VĚDY. | G37: =ROUND(Tabulka5789101112131415161718192021222324252627282930313233343536373839404142434445464748[[#This Row],[Kapacita - počet polic]]*Tabulka5789101112131415161718192021222324252627282930313233343536373839404142434445464748[[#This Row],[Kapacita - rozměr polic]]*IFERROR(VLOOKUP(Tabulka5789101112131415161718192021222324252627282930313233343536373839404142434445464748[[#This Row],[Označení]],OCHy[#All],2,FALSE),0.6),0) -> 18 | H37: 0.5 | J37: 86 | K37: G, O, W | L37: 0.6
A38: =IFERROR(VLOOKUP(B38,Pobočky!$A$1:$C$45,3,FALSE)," ") -> 62 | B38: Barrandov | C38: =IFERROR(VLOOKUP(B38,Pobočky!$A$1:$C$45,2,FALSE)," ") -> Jihozápad | D38: BAR-NAUDO | E38: Naučná - dospělí | F38: C - DOMÁCNOST. | G38: =ROUND(Tabulka5789101112131415161718192021222324252627282930313233343536373839404142434445464748[[#This Row],[Kapacita - počet polic]]*Tabulka5789101112131415161718192021222324252627282930313233343536373839404142434445464748[[#This Row],[Kapacita - rozměr polic]]*IFERROR(VLOOKUP(Tabulka5789101112131415161718192021222324252627282930313233343536373839404142434445464748[[#This Row],[Označení]],OCHy[#All],2,FALSE),0.6),0) -> 362 | H38: 8 | J38: 73 | L38: 0.7
A39: =IFERROR(VLOOKUP(B39,Pobočky!$A$1:$C$45,3,FALSE)," ") -> 62 | B39: Barrandov | C39: =IFERROR(VLOOKUP(B39,Pobočky!$A$1:$C$45,2,FALSE)," ") -> Jihozápad | D39: BAR-NAUDO | E39: Naučná - dospělí | F39: D - DĚJINY. DĚJEPIS. | G39: =ROUND(Tabulka5789101112131415161718192021222324252627282930313233343536373839404142434445464748[[#This Row],[Kapacita - počet polic]]*Tabulka5789101112131415161718192021222324252627282930313233343536373839404142434445464748[[#This Row],[Kapacita - rozměr polic]]*IFERROR(VLOOKUP(Tabulka5789101112131415161718192021222324252627282930313233343536373839404142434445464748[[#This Row],[Označení]],OCHy[#All],2,FALSE),0.6),0) -> 499 | H39: 18 | J39: 73 | L39: 0.7
A40: =IFERROR(VLOOKUP(B40,Pobočky!$A$1:$C$45,3,FALSE)," ") -> 62 | B40: Barrandov | C40: =IFERROR(VLOOKUP(B40,Pobočky!$A$1:$C$45,2,FALSE)," ") -> Jihozápad | D40: BAR-NAUDO | E40: Naučná - dospělí | F40: E - ZEMĚPIS. VLASTIVĚDA. ETNOGRAFIE. | G40: =ROUND(Tabulka5789101112131415161718192021222324252627282930313233343536373839404142434445464748[[#This Row],[Kapacita - počet polic]]*Tabulka5789101112131415161718192021222324252627282930313233343536373839404142434445464748[[#This Row],[Kapacita - rozměr polic]]*IFERROR(VLOOKUP(Tabulka5789101112131415161718192021222324252627282930313233343536373839404142434445464748[[#This Row],[Označení]],OCHy[#All],2,FALSE),0.6),0) -> 241 | H40: 6 | J40: 73 | L40: 0.7
...

Sheet Cibulka
A1: Pobočka č. | B1: Pobočka | C1: Oblast | D1: Lokace - systémové označení (Koniáš) | E1: Typ | F1: Označení | G1: Kapacita svazky | H1: Kapacita - počet polic | I1: Kapacita - současný stav | J1: Kapacita - rozměr polic | K1: Poznámka | L1: Jakou byste doporučili ideální naplněnost?
A2: =IFERROR(VLOOKUP(B2,Pobočky!$A$1:$C$45,3,FALSE)," ") -> 30 | B2: Cibulka | C2: =IFERROR(VLOOKUP(B2,Pobočky!$A$1:$C$45,2,FALSE)," ") -> Jihozápad | D2: CI3-LITDE | E2: Beletrie - děti | F2: A - BELETRIE VŠEOBECNĚ. | G2: =ROUND(Tabulka5789101112131415161718192021222324252627282930313233343536373839404142434445[[#This Row],[Kapacita - počet polic]]*Tabulka5789101112131415161718192021222324252627282930313233343536373839404142434445[[#This Row],[Kapacita - rozměr polic]]*IFERROR(VLOOKUP(Tabulka5789101112131415161718192021222324252627282930313233343536373839404142434445[[#This Row],[Označení]],OCHy[#All],2,FALSE),0.6),0) -> 269 | H2: 6 | J2: 80 | K2: A4 + A1 | L2: 0.7
A3: =IFERROR(VLOOKUP(B3,Pobočky!$A$1:$C$45,3,FALSE)," ") -> 30 | B3: Cibulka | C3: =IFERROR(VLOOKUP(B3,Pobočky!$A$1:$C$45,2,FALSE)," ") -> Jihozápad | D3: CI3-LITDE | E3: Beletrie - děti | F3: A - BELETRIE VŠEOBECNĚ. | G3: =ROUND(Tabulka5789101112131415161718192021222324252627282930313233343536373839404142434445[[#This Row],[Kapacita - počet polic]]*Tabulka5789101112131415161718192021222324252627282930313233343536373839404142434445[[#This Row],[Kapacita - rozměr polic]]*IFERROR(VLOOKUP(Tabulka5789101112131415161718192021222324252627282930313233343536373839404142434445[[#This Row],[Označení]],OCHy[#All],2,FALSE),0.6),0) -> 112 | H3: 4 | J3: 50 | K3: A2 | L3: 0.7
A4: =IFERROR(VLOOKUP(B4,Pobočky!$A$1:$C$45,3,FALSE)," ") -> 30 | B4: Cibulka | C4: =IFERROR(VLOOKUP(B4,Pobočky!$A$1:$C$45,2,FALSE)," ") -> Jihozápad | D4: CI3-LITDE | E4: Beletrie - děti | F4: A - BELETRIE VŠEOBECNĚ. | G4: =ROUND(Tabulka5789101112131415161718192021222324252627282930313233343536373839404142434445[[#This Row],[Kapacita - počet polic]]*Tabulka5789101112131415161718192021222324252627282930313233343536373839404142434445[[#This Row],[Kapacita - rozměr polic]]*IFERROR(VLOOKUP(Tabulka5789101112131415161718192021222324252627282930313233343536373839404142434445[[#This Row],[Označení]],OCHy[#All],2,FALSE),0.6),0) -> 224 | H4: 5 | J4: 80 | K4: A3 | L4: 0.7
A5: =IFERROR(VLOOKUP(B5,Pobočky!$A$1:$C$45,3,FALSE)," ") -> 30 | B5: Cibulka | C5: =IFERROR(VLOOKUP(B5,Pobočky!$A$1:$C$45,2,FALSE)," ") -> Jihozápad | D5: CI3-LITDE | E5: Beletrie - děti | F5: A - BELETRIE VŠEOBECNĚ. | G5: =ROUND(Tabulka5789101112131415161718192021222324252627282930313233343536373839404142434445[[#This Row],[Kapacita - počet polic]]*Tabulka5789101112131415161718192021222324252627282930313233343536373839404142434445[[#This Row],[Kapacita - rozměr polic]]*IFERROR(VLOOKUP(Tabulka5789101112131415161718192021222324252627282930313233343536373839404142434445[[#This Row],[Označení]],OCHy[#All],2,FALSE),0.6),0) -> 28 | H5: 1 | J5: 50 | K5: A3 | L5: 0.7
A6: =IFERROR(VLOOKUP(B6,Pobočky!$A$1:$C$45,3,FALSE)," ") -> 30 | B6: Cibulka | C6: =IFERROR(VLOOKUP(B6,Pobočky!$A$1:$C$45,2,FALSE)," ") -> Jihozápad | D6: CI3-LITDE | E6: Beletrie - děti | F6: J - CIZOJAZYČNÁ BELETRIE. | G6: =ROUND(Tabulka5789101112131415161718192021222324252627282930313233343536373839404142434445[[#This Row],[Kapacita - počet polic]]*Tabulka5789101112131415161718192021222324252627282930313233343536373839404142434445[[#This Row],[Kapacita - rozměr polic]]*IFERROR(VLOOKUP(Tabulka5789101112131415161718192021222324252627282930313233343536373839404142434445[[#This Row],[Označení]],OCHy[#All],2,FALSE),0.6),0) -> 12 | H6: 1 | J6: 34 | L6: 0.7
A7: =IFERROR(VLOOKUP(B7,Pobočky!$A$1:$C$45,3,FALSE)," ") -> 30 | B7: Cibulka | C7: =IFERROR(VLOOKUP(B7,Pobočky!$A$1:$C$45,2,FALSE)," ") -> Jihozápad | D7: CI3-LITDE | E7: Beletrie - děti | F7: A - BELETRIE VŠEOBECNĚ. | G7: =ROUND(Tabulka5789101112131415161718192021222324252627282930313233343536373839404142434445[[#This Row],[Kapacita - počet polic]]*Tabulka5789101112131415161718192021222324252627282930313233343536373839404142434445[[#This Row],[Kapacita - rozměr polic]]*IFERROR(VLOOKUP(Tabulka5789101112131415161718192021222324252627282930313233343536373839404142434445[[#This Row],[Označení]],OCHy[#All],2,FALSE),0.6),0) -> 19 | H7: 1 | J7: 34 | K7: leporela | L7: 0.5
A8: =IFERROR(VLOOKUP(B8,Pobočky!$A$1:$C$45,3,FALSE)," ") -> 30 | B8: Cibulka | C8: =IFERROR(VLOOKUP(B8,Pobočky!$A$1:$C$45,2,FALSE)," ") -> Jihozápad | D8: CI3-LITDE | E8: Beletrie - děti | F8: A - BELETRIE VŠEOBECNĚ. | G8: =ROUND(Tabulka5789101112131415161718192021222324252627282930313233343536373839404142434445[[#This Row],[Kapacita - počet polic]]*Tabulka5789101112131415161718192021222324252627282930313233343536373839404142434445[[#This Row],[Kapacita - rozměr polic]]*IFERROR(VLOOKUP(Tabulka5789101112131415161718192021222324252627282930313233343536373839404142434445[[#This Row],[Označení]],OCHy[#All],2,FALSE),0.6),0) -> 19 | H8: 1 | J8: 34 | K8: komiksy | L8: 0.5
A9: =IFERROR(VLOOKUP(B9,Pobočky!$A$1:$C$45,3,FALSE)," ") -> 30 | B9: Cibulka | C9: =IFERROR(VLOOKUP(B9,Pobočky!$A$1:$C$45,2,FALSE)," ") -> Jihozápad | D9: CI3-LITDE | E9: Beletrie - děti | F9: B - POEZIE. | G9: =ROUND(Tabulka5789101112131415161718192021222324252627282930313233343536373839404142434445[[#This Row],[Kapacita - počet polic]]*Tabulka5789101112131415161718192021222324252627282930313233343536373839404142434445[[#This Row],[Kapacita - rozměr polic]]*IFERROR(VLOOKUP(Tabulka5789101112131415161718192021222324252627282930313233343536373839404142434445[[#This Row],[Označení]],OCHy[#All],2,FALSE),0.6),0) -> 20 | H9: 1 | J9: 34 | L9: 0.7
A10: =IFERROR(VLOOKUP(B10,Pobočky!$A$1:$C$45,3,FALSE)," ") -> 30 | B10: Cibulka | C10: =IFERROR(VLOOKUP(B10,Pobočky!$A$1:$C$45,2,FALSE)," ") -> Jihozápad | D10: CI3-LITDE | E10: Naučná - děti | F10: C - DOMÁCNOST. | G10: =ROUND(Tabulka5789101112131415161718192021222324252627282930313233343536373839404142434445[[#This Row],[Kapacita - počet polic]]*Tabulka5789101112131415161718192021222324252627282930313233343536373839404142434445[[#This Row],[Kapacita - rozměr polic]]*IFERROR(VLOOKUP(Tabulka5789101112131415161718192021222324252627282930313233343536373839404142434445[[#This Row],[Označení]],OCHy[#All],2,FALSE),0.6),0) -> 12 | H10: 0.25 | J10: 80 | L10: 0.6
A11: =IFERROR(VLOOKUP(B11,Pobočky!$A$1:$C$45,3,FALSE)," ") -> 30 | B11: Cibulka | C11: =IFERROR(VLOOKUP(B11,Pobočky!$A$1:$C$45,2,FALSE)," ") -> Jihozápad | D11: CI3-LITDE | E11: Naučná - děti | F11: D - DĚJINY. DĚJEPIS. | G11: =ROUND(Tabulka5789101112131415161718192021222324252627282930313233343536373839404142434445[[#This Row],[Kapacita - počet polic]]*Tabulka5789101112131415161718192021222324252627282930313233343536373839404142434445[[#This Row],[Kapacita - rozměr polic]]*IFERROR(VLOOKUP(Tabulka5789101112131415161718192021222324252627282930313233343536373839404142434445[[#This Row],[Označení]],OCHy[#All],2,FALSE),0.6),0) -> 23 | H11: 0.75 | J11: 80 | L11: 0.6
A12: =IFERROR(VLOOKUP(B12,Pobočky!$A$1:$C$45,3,FALSE)," ") -> 30 | B12: Cibulka | C12: =IFERROR(VLOOKUP(B12,Pobočky!$A$1:$C$45,2,FALSE)," ") -> Jihozápad | D12: CI3-LITDE | E12: Naučná - děti | F12: E - ZEMĚPIS. VLASTIVĚDA. ETNOGRAFIE. | G12: =ROUND(Tabulka5789101112131415161718192021222324252627282930313233343536373839404142434445[[#This Row],[Kapacita - počet polic]]*Tabulka5789101112131415161718192021222324252627282930313233343536373839404142434445[[#This Row],[Kapacita - rozměr polic]]*IFERROR(VLOOKUP(Tabulka5789101112131415161718192021222324252627282930313233343536373839404142434445[[#This Row],[Označení]],OCHy[#All],2,FALSE),0.6),0) -> 9 | H12: 0.2 | J12: 80 | L12: 0.6
A13: =IFERROR(VLOOKUP(B13,Pobočky!$A$1:$C$45,3,FALSE)," ") -> 30 | B13: Cibulka | C13: =IFERROR(VLOOKUP(B13,Pobočky!$A$1:$C$45,2,FALSE)," ") -> Jihozápad | D13: CI3-LITDE | E13: Naučná - děti | F13: K - PŘÍRODNÍ VĚDY. | G13: =ROUND(Tabulka5789101112131415161718192021222324252627282930313233343536373839404142434445[[#This Row],[Kapacita - počet polic]]*Tabulka5789101112131415161718192021222324252627282930313233343536373839404142434445[[#This Row],[Kapacita - rozměr polic]]*IFERROR(VLOOKUP(Tabulka5789101112131415161718192021222324252627282930313233343536373839404142434445[[#This Row],[Označení]],OCHy[#All],2,FALSE),0.6),0) -> 69 | H13: 1.7 | J13: 80 | L13: 0.6
A14: =IFERROR(VLOOKUP(B14,Pobočky!$A$1:$C$45,3,FALSE)," ") -> 30 | B14: Cibulka | C14: =IFERROR(VLOOKUP(B14,Pobočky!$A$1:$C$45,2,FALSE)," ") -> Jihozápad | D14: CI3-LITDE | E14: Naučná - děti | F14: L - FILOZOFIE. PSYCHOLOGIE. ESTETIKA. ETIKA. LOGIKA. NÁBOŽENSTVÍ. | G14: =ROUND(Tabulka5789101112131415161718192021222324252627282930313233343536373839404142434445[[#This Row],[Kapacita - počet polic]]*Tabulka5789101112131415161718192021222324252627282930313233343536373839404142434445[[#This Row],[Kapacita - rozměr polic]]*IFERROR(VLOOKUP(Tabulka5789101112131415161718192021222324252627282930313233343536373839404142434445[[#This Row],[Označení]],OCHy[#All],2,FALSE),0.6),0) -> 9 | H14: 0.25 | J14: 80 | L14: 0.6
A15: =IFERROR(VLOOKUP(B15,Pobočky!$A$1:$C$45,3,FALSE)," ") -> 30 | B15: Cibulka | C15: =IFERROR(VLOOKUP(B15,Pobočky!$A$1:$C$45,2,FALSE)," ") -> Jihozápad | D15: CI3-LITDE | E15: Naučná - děti | F15: N - PEDAGOGIKA. ŠKOLSTVÍ. VÝCHOVA. VZDĚLÁVÁNÍ. | G15: =ROUND(Tabulka5789101112131415161718192021222324252627282930313233343536373839404142434445[[#This Row],[Kapacita - počet polic]]*Tabulka5789101112131415161718192021222324252627282930313233343536373839404142434445[[#This Row],[Kapacita - rozměr polic]]*IFERROR(VLOOKUP(Tabulka5789101112131415161718192021222324252627282930313233343536373839404142434445[[#This Row],[Označení]],OCHy[#All],2,FALSE),0.6),0) -> 17 | H15: 0.35 | J15: 80 | L15: 0.6
A16: =IFERROR(VLOOKUP(B16,Pobočky!$A$1:$C$45,3,FALSE)," ") -> 30 | B16: Cibulka | C16: =IFERROR(VLOOKUP(B16,Pobočky!$A$1:$C$45,2,FALSE)," ") -> Jihozápad | D16: CI3-LITDE | E16: Naučná - děti | F16: T - TECHNIKA. | G16: =ROUND(Tabulka5789101112131415161718192021222324252627282930313233343536373839404142434445[[#This Row],[Kapacita - počet polic]]*Tabulka5789101112131415161718192021222324252627282930313233343536373839404142434445[[#This Row],[Kapacita - rozměr polic]]*IFERROR(VLOOKUP(Tabulka5789101112131415161718192021222324252627282930313233343536373839404142434445[[#This Row],[Označení]],OCHy[#All],2,FALSE),0.6),0) -> 12 | H16: 0.25 | J16: 80 | L16: 0.6
A17: =IFERROR(VLOOKUP(B17,Pobočky!$A$1:$C$45,3,FALSE)," ") -> 30 | B17: Cibulka | C17: =IFERROR(VLOOKUP(B17,Pobočky!$A$1:$C$45,2,FALSE)," ") -> Jihozápad | D17: CI3-LITDE | E17: Naučná - děti | F17: V - HUDBA. | G17: =ROUND(Tabulka5789101112131415161718192021222324252627282930313233343536373839404142434445[[#This Row],[Kapacita - počet polic]]*Tabulka5789101112131415161718192021222324252627282930313233343536373839404142434445[[#This Row],[Kapacita - rozměr polic]]*IFERROR(VLOOKUP(Tabulka5789101112131415161718192021222324252627282930313233343536373839404142434445[[#This Row],[Označení]],OCHy[#All],2,FALSE),0.6),0) -> 9 | H17: 0.25 | J17: 80 | L17: 0.6
A18: =IFERROR(VLOOKUP(B18,Pobočky!$A$1:$C$45,3,FALSE)," ") -> 30 | B18: Cibulka | C18: =IFERROR(VLOOKUP(B18,Pobočky!$A$1:$C$45,2,FALSE)," ") -> Jihozápad | D18: CI3-LITDE | E18: Naučná - děti | F18: Y - TĚLESNÁ VÝCHOVA A SPORT | G18: =ROUND(Tabulka5789101112131415161718192021222324252627282930313233343536373839404142434445[[#This Row],[Kapacita - počet polic]]*Tabulka5789101112131415161718192021222324252627282930313233343536373839404142434445[[#This Row],[Kapacita - rozměr polic]]*IFERROR(VLOOKUP(Tabulka5789101112131415161718192021222324252627282930313233343536373839404142434445[[#This Row],[Označení]],OCHy[#All],2,FALSE),0.6),0) -> 11 | H18: 0.25 | J18: 80 | L18: 0.6
A19: =IFERROR(VLOOKUP(B19,Pobočky!$A$1:$C$45,3,FALSE)," ") -> 30 | B19: Cibulka | C19: =IFERROR(VLOOKUP(B19,Pobočky!$A$1:$C$45,2,FALSE)," ") -> Jihozápad | D19: CI3-LITDE | E19: Naučná - děti | F19: Z - ZEMĚDĚLSTVÍ. LESNICTVÍ. MYSLIVOST. | G19: =ROUND(Tabulka5789101112131415161718192021222324252627282930313233343536373839404142434445[[#This Row],[Kapacita - počet polic]]*Tabulka5789101112131415161718192021222324252627282930313233343536373839404142434445[[#This Row],[Kapacita - rozměr polic]]*IFERROR(VLOOKUP(Tabulka5789101112131415161718192021222324252627282930313233343536373839404142434445[[#This Row],[Označení]],OCHy[#All],2,FALSE),0.6),0) -> 13 | H19: 0.25 | J19: 80 | L19: 0.6
A20: =IFERROR(VLOOKUP(B20,Pobočky!$A$1:$C$45,3,FALSE)," ") -> 30 | B20: Cibulka | C20: =IFERROR(VLOOKUP(B20,Pobočky!$A$1:$C$45,2,FALSE)," ") -> Jihozápad | D20: CI3-LITDE | E20: Naučná - děti | G20: =ROUND(Tabulka5789101112131415161718192021222324252627282930313233343536373839404142434445[[#This Row],[Kapacita - počet polic]]*Tabulka5789101112131415161718192021222324252627282930313233343536373839404142434445[[#This Row],[Kapacita - rozměr polic]]*IFERROR(VLOOKUP(Tabulka5789101112131415161718192021222324252627282930313233343536373839404142434445[[#This Row],[Označení]],OCHy[#All],2,FALSE),0.6),0) -> 24 | H20: 0.5 | J20: 80 | K20: OSTATNÍ NAUČNÁ | L20: 0.6
